Workbook

Sheet Inputs
A1: Parameter | B1: Value
A3: InvCost | B3: 0.25
A4: BackCost | B4: 1
A5: ExpectedDemand | B5: 100
A6: OrderDelay | B6: 2
A7: ShipDelay | B7: 2
A8: ProdDelay | B8: 2
A10: Mode | B10: Auto
A11: ScenarioIndex | B11: 1
A12: DemandLevel (1=Low,2=Base,3=High) | B12: 2
A13: TargetWeeks_Retailer | B13: =INDEX($C$27:$F$29,$B$11,1)
A14: TargetWeeks_Wholesaler | B14: =INDEX($C$27:$F$29,$B$11,2)
A15: TargetWeeks_Distributor | B15: =INDEX($C$27:$F$29,$B$11,3)
A16: TargetWeeks_Factory | B16: =INDEX($C$27:$F$29,$B$11,4)
A18: InitialInventory | B18: 100
A19: InitialShipPipe1 | B19: 50
A20: InitialShipPipe2 | B20: 50
A21: InitialOrderPipe1 | B21: 0
A22: InitialOrderPipe2 | B22: 0
A23: DefaultOrderWeek1 | B23: 100
A24: ScenarioName | B24: =INDEX($B$27:$B$29,$B$11)
A25: DemandLevelName | B25: =CHOOSE($B$12,"Low","Base","High")
A26: ScenarioIndex | B26: ScenarioName | C26: TargetWeeks_Retailer | D26: TargetWeeks_Wholesaler | E26: TargetWeeks_Distributor | F26: TargetWeeks_Factory | G26: Notes
A27: 1 | B27: Simulation - Scenario 1 - HighInv | C27: 4 | D27: 4 | E27: 8 | F27: 8 | G27: High inventory, lowest risk of backlog
A28: 2 | B28: Simulation - Scenario 2 - Balanced | C28: 2 | D28: 4 | E28: 5 | F28: 5 | G28: Balanced inventory and backlog tradeoff
A29: 3 | B29: Simulation - Scenario 3 - MinCost | C29: 1 | D29: 4 | E29: 5 | F29: 6 | G29: Cost-focused baseline policy (editable)
A31: Scenario Summary
A32: Scenario | B32: Demand Used | C32: Policy Intent | D32: Weekly KPI | E32: Final KPI
A33: Simulation - Scenario 1 - HighInv | B33: Selected in Inputs (Low/Base/High) | C33: Reduce backlog risk | D33: TotInvCost + TotBackCost (= TotWeekCost) | E33: =Scn1_View!AS39
A34: Simulation - Scenario 2 - Balanced | B34: Selected in Inputs (Low/Base/High) | C34: Balance inventory and backlog | D34: TotInvCost + TotBackCost (= TotWeekCost) | E34: =Scn2_View!AS39
A35: Simulation - Scenario 3 - MinCost | B35: Selected in Inputs (Low/Base/High) | C35: Minimize total cost | D35: TotInvCost + TotBackCost (= TotWeekCost) | E35: =Scn3_View!AS39

Sheet Demand
A1: Week | B1: BaseDemand | C1: LowDemand | D1: HighDemand | E1: ActiveDemand
A2: 1 | B2: 100 | C2: 64 | D2: 91 | E2: =CHOOSE(Inputs!$B$12,C2,B2,D2)
A3: 2 | B3: 100 | C3: 96 | D3: 139 | E3: =CHOOSE(Inputs!$B$12,C3,B3,D3)
A4: 3 | B4: 100 | C4: 76 | D4: 109 | E4: =CHOOSE(Inputs!$B$12,C4,B4,D4)
A5: 4 | B5: 100 | C5: 88 | D5: 127 | E5: =CHOOSE(Inputs!$B$12,C5,B5,D5)
A6: 5 | B6: 100 | C6: 72 | D6: 103 | E6: =CHOOSE(Inputs!$B$12,C6,B6,D6)
A7: 6 | B7: 100 | C7: 104 | D7: 151 | E7: =CHOOSE(Inputs!$B$12,C7,B7,D7)
A8: 7 | B8: 100 | C8: 68 | D8: 97 | E8: =CHOOSE(Inputs!$B$12,C8,B8,D8)
A9: 8 | B9: 100 | C9: 92 | D9: 133 | E9: =CHOOSE(Inputs!$B$12,C9,B9,D9)
A10: 9 | B10: 100 | C10: 80 | D10: 115 | E10: =CHOOSE(Inputs!$B$12,C10,B10,D10)
A11: 10 | B11: 100 | C11: 84 | D11: 121 | E11: =CHOOSE(Inputs!$B$12,C11,B11,D11)
A12: 11 | B12: 100 | C12: 60 | D12: 85 | E12: =CHOOSE(Inputs!$B$12,C12,B12,D12)
A13: 12 | B13: 100 | C13: 100 | D13: 145 | E13: =CHOOSE(Inputs!$B$12,C13,B13,D13)
... A36: 35 | B36: 100 | C36: 48 | D36: 67 | E36: =CHOOSE(Inputs!$B$12,C36,B36,D36)

Sheet Summary
A1: Demand Used | B1: High demand profile | C1: Base demand profile | D1: Low demand profile
A2: Scenario
A3: Simulation - Scenario 1 - HighInv | B3: 285947.25 | C3: 215350 | D3: 141272.5
A4: Simulation - Scenario 2 - Balanced | B4: 229725.75 | C4: 114350 | D4: 15661.75
A5: Simulation - Scenario 3 - MinCost | B5: 127317.5 | C5: 18600 | D5: 6833.25

Sheet S1_D1_Retailer
A1: Week | B1: CustomerDemand | C1: In | D1: Recv | E1: BegInv | F1: BegBacklog | G1: TotalReq | H1: Ship | I1: EndInv | J1: EndBacklog | K1: InvCost | L1: BackCost | M1: WeekCost | N1: CumulativeCost | O1: OrderManual | P1: OrderPlaced | Q1: OrderPipe1 | R1: OrderPipe2 | S1: ShipPipe1 | T1: ShipPipe2 | U1: InventoryPos | V1: TargetLevel | W1: SuggestedOrder
A2: 1 | B2: 64 | C2: 64 | D2: 50 | E2: 100 | F2: 0 | G2: 64 | H2: 64 | I2: 86 | J2: 0 | K2: 21.5 | L2: 0 | M2: 21.5 | N2: 21.5 | P2: 264 | Q2: 0 | R2: 0 | S2: 0 | T2: 0 | U2: 0 | V2: 0 | W2: 0
A3: 2 | B3: 96 | C3: 96 | D3: 50 | E3: 86 | F3: 0 | G3: 96 | H3: 96 | I3: 40 | J3: 0 | K3: 10 | L3: 0 | M3: 10 | N3: 31.5 | P3: 360 | Q3: 0 | R3: 0 | S3: 0 | T3: 0 | U3: 0 | V3: 0 | W3: 0
A4: 3 | B4: 76 | C4: 76 | D4: 0 | E4: 40 | F4: 0 | G4: 76 | H4: 40 | I4: 0 | J4: 36 | K4: 0 | L4: 36 | M4: 36 | N4: 67.5 | P4: 436 | Q4: 0 | R4: 0 | S4: 0 | T4: 0 | U4: 0 | V4: 0 | W4: 0
A5: 4 | B5: 88 | C5: 88 | D5: 0 | E5: 0 | F5: 36 | G5: 124 | H5: 0 | I5: 0 | J5: 124 | K5: 0 | L5: 124 | M5: 124 | N5: 191.5 | P5: 324 | Q5: 0 | R5: 0 | S5: 0 | T5: 0 | U5: 0 | V5: 0 | W5: 0
A6: 5 | B6: 72 | C6: 72 | D6: 200 | E6: 0 | F6: 124 | G6: 196 | H6: 196 | I6: 4 | J6: 0 | K6: 1 | L6: 0 | M6: 1 | N6: 192.5 | P6: 396 | Q6: 0 | R6: 0 | S6: 0 | T6: 0 | U6: 0 | V6: 0 | W6: 0
A7: 6 | B7: 104 | C7: 104 | D7: 0 | E7: 4 | F7: 0 | G7: 104 | H7: 4 | I7: 0 | J7: 100 | K7: 0 | L7: 100 | M7: 100 | N7: 292.5 | P7: 300 | Q7: 0 | R7: 0 | S7: 0 | T7: 0 | U7: 0 | V7: 0 | W7: 0
A8: 7 | B8: 68 | C8: 68 | D8: 200 | E8: 0 | F8: 100 | G8: 168 | H8: 168 | I8: 32 | J8: 0 | K8: 8 | L8: 0 | M8: 8 | N8: 300.5 | P8: 368 | Q8: 0 | R8: 0 | S8: 0 | T8: 0 | U8: 0 | V8: 0 | W8: 0
A9: 8 | B9: 92 | C9: 92 | D9: 0 | E9: 32 | F9: 0 | G9: 92 | H9: 32 | I9: 0 | J9: 60 | K9: 0 | L9: 60 | M9: 60 | N9: 360.5 | P9: 60 | Q9: 0 | R9: 0 | S9: 0 | T9: 0 | U9: 0 | V9: 0 | W9: 0
A10: 9 | B10: 80 | C10: 80 | D10: 400 | E10: 0 | F10: 60 | G10: 140 | H10: 140 | I10: 260 | J10: 0 | K10: 65 | L10: 0 | M10: 65 | N10: 425.5 | P10: 0 | Q10: 0 | R10: 0 | S10: 0 | T10: 0 | U10: 0 | V10: 0 | W10: 0
A11: 10 | B11: 84 | C11: 84 | D11: 300 | E11: 260 | F11: 0 | G11: 84 | H11: 84 | I11: 476 | J11: 0 | K11: 119 | L11: 0 | M11: 119 | N11: 544.5 | P11: 0 | Q11: 0 | R11: 0 | S11: 0 | T11: 0 | U11: 0 | V11: 0 | W11: 0
A12: 11 | B12: 60 | C12: 60 | D12: 500 | E12: 476 | F12: 0 | G12: 60 | H12: 60 | I12: 916 | J12: 0 | K12: 229 | L12: 0 | M12: 229 | N12: 773.5 | P12: 0 | Q12: 0 | R12: 0 | S12: 0 | T12: 0 | U12: 0 | V12: 0 | W12: 0
A13: 12 | B13: 100 | C13: 100 | D13: 300 | E13: 916 | F13: 0 | G13: 100 | H13: 100 | I13: 1116 | J13: 0 | K13: 279 | L13: 0 | M13: 279 | N13: 1052.5 | P13: 0 | Q13: 0 | R13: 0 | S13: 0 | T13: 0 | U13: 0 | V13: 0 | W13: 0
... A36: 35 | B36: 48 | C36: 48 | D36: 195 | E36: 122 | F36: 0 | G36: 48 | H36: 48 | I36: 269 | J36: 0 | K36: 67.25 | L36: 0 | M36: 67.25 | N36: 5525.75 | P36: 0 | Q36: 0 | R36: 0 | S36: 0 | T36: 0 | U36: 0 | V36: 0 | W36: 0

Sheet S1_D1_Wholesaler
A1: Week | B1: CustomerDemand | C1: In | D1: Recv | E1: BegInv | F1: BegBacklog | G1: TotalReq | H1: Ship | I1: EndInv | J1: EndBacklog | K1: InvCost | L1: BackCost | M1: WeekCost | N1: CumulativeCost | O1: OrderManual | P1: OrderPlaced | Q1: OrderPipe1 | R1: OrderPipe2 | S1: ShipPipe1 | T1: ShipPipe2 | U1: InventoryPos | V1: TargetLevel | W1: SuggestedOrder
A2: 1 | B2: 0 | C2: 0 | D2: 50 | E2: 100 | F2: 0 | G2: 0 | H2: 0 | I2: 150 | J2: 0 | K2: 37.5 | L2: 0 | M2: 37.5 | N2: 37.5 | P2: 200 | Q2: 0 | R2: 0 | S2: 0 | T2: 0 | U2: 0 | V2: 0 | W2: 0
A3: 2 | B3: 0 | C3: 0 | D3: 50 | E3: 150 | F3: 0 | G3: 0 | H3: 0 | I3: 200 | J3: 0 | K3: 50 | L3: 0 | M3: 50 | N3: 87.5 | P3: 200 | Q3: 0 | R3: 0 | S3: 0 | T3: 0 | U3: 0 | V3: 0 | W3: 0
A4: 3 | B4: 264 | C4: 264 | D4: 0 | E4: 200 | F4: 0 | G4: 264 | H4: 200 | I4: 0 | J4: 64 | K4: 0 | L4: 64 | M4: 64 | N4: 151.5 | P4: 464 | Q4: 0 | R4: 0 | S4: 0 | T4: 0 | U4: 0 | V4: 0 | W4: 0
A5: 4 | B5: 360 | C5: 360 | D5: 0 | E5: 0 | F5: 64 | G5: 424 | H5: 0 | I5: 0 | J5: 424 | K5: 0 | L5: 424 | M5: 424 | N5: 575.5 | P5: 624 | Q5: 0 | R5: 0 | S5: 0 | T5: 0 | U5: 0 | V5: 0 | W5: 0
A6: 5 | B6: 436 | C6: 436 | D6: 200 | E6: 0 | F6: 424 | G6: 860 | H6: 200 | I6: 0 | J6: 660 | K6: 0 | L6: 660 | M6: 660 | N6: 1235.5 | P6: 1060 | Q6: 0 | R6: 0 | S6: 0 | T6: 0 | U6: 0 | V6: 0 | W6: 0
A7: 6 | B7: 324 | C7: 324 | D7: 0 | E7: 0 | F7: 660 | G7: 984 | H7: 0 | I7: 0 | J7: 984 | K7: 0 | L7: 984 | M7: 984 | N7: 2219.5 | P7: 984 | Q7: 0 | R7: 0 | S7: 0 | T7: 0 | U7: 0 | V7: 0 | W7: 0
A8: 7 | B8: 396 | C8: 396 | D8: 400 | E8: 0 | F8: 984 | G8: 1380 | H8: 400 | I8: 0 | J8: 980 | K8: 0 | L8: 980 | M8: 980 | N8: 3199.5 | P8: 1080 | Q8: 0 | R8: 0 | S8: 0 | T8: 0 | U8: 0 | V8: 0 | W8: 0
A9: 8 | B9: 300 | C9: 300 | D9: 300 | E9: 0 | F9: 980 | G9: 1280 | H9: 300 | I9: 0 | J9: 980 | K9: 0 | L9: 980 | M9: 980 | N9: 4179.5 | P9: 880 | Q9: 0 | R9: 0 | S9: 0 | T9: 0 | U9: 0 | V9: 0 | W9: 0
A10: 9 | B10: 368 | C10: 368 | D10: 500 | E10: 0 | F10: 980 | G10: 1348 | H10: 500 | I10: 0 | J10: 848 | K10: 0 | L10: 848 | M10: 848 | N10: 5027.5 | P10: 948 | Q10: 0 | R10: 0 | S10: 0 | T10: 0 | U10: 0 | V10: 0 | W10: 0
A11: 10 | B11: 60 | C11: 60 | D11: 300 | E11: 0 | F11: 848 | G11: 908 | H11: 300 | I11: 0 | J11: 608 | K11: 0 | L11: 608 | M11: 608 | N11: 5635.5 | P11: 644 | Q11: 0 | R11: 0 | S11: 0 | T11: 0 | U11: 0 | V11: 0 | W11: 0
A12: 11 | B12: 0 | C12: 0 | D12: 364 | E12: 0 | F12: 608 | G12: 608 | H12: 364 | I12: 0 | J12: 244 | K12: 0 | L12: 244 | M12: 244 | N12: 5879.5 | P12: 208 | Q12: 0 | R12: 0 | S12: 0 | T12: 0 | U12: 0 | V12: 0 | W12: 0
A13: 12 | B13: 0 | C13: 0 | D13: 436 | E13: 0 | F13: 244 | G13: 244 | H13: 244 | I13: 192 | J13: 0 | K13: 48 | L13: 0 | M13: 48 | N13: 5927.5 | P13: 0 | Q13: 0 | R13: 0 | S13: 0 | T13: 0 | U13: 0 | V13: 0 | W13: 0
... A36: 35 | B36: 192 | C36: 192 | D36: 0 | E36: 4381 | F36: 0 | G36: 192 | H36: 192 | I36: 4189 | J36: 0 | K36: 1047.25 | L36: 0 | M36: 1047.25 | N36: 31122.75 | P36: 0 | Q36: 0 | R36: 0 | S36: 0 | T36: 0 | U36: 0 | V36: 0 | W36: 0

Sheet S1_D1_Distributor
A1: Week | B1: CustomerDemand | C1: In | D1: Recv | E1: BegInv | F1: BegBacklog | G1: TotalReq | H1: Ship | I1: EndInv | J1: EndBacklog | K1: InvCost | L1: BackCost | M1: WeekCost | N1: CumulativeCost | O1: OrderManual | P1: OrderPlaced | Q1: OrderPipe1 | R1: OrderPipe2 | S1: ShipPipe1 | T1: ShipPipe2 | U1: InventoryPos | V1: TargetLevel | W1: SuggestedOrder
A2: 1 | B2: 0 | C2: 0 | D2: 50 | E2: 100 | F2: 0 | G2: 0 | H2: 0 | I2: 150 | J2: 0 | K2: 37.5 | L2: 0 | M2: 37.5 | N2: 37.5 | P2: 400 | Q2: 0 | R2: 0 | S2: 0 | T2: 0 | U2: 0 | V2: 0 | W2: 0
A3: 2 | B3: 0 | C3: 0 | D3: 50 | E3: 150 | F3: 0 | G3: 0 | H3: 0 | I3: 200 | J3: 0 | K3: 50 | L3: 0 | M3: 50 | N3: 87.5 | P3: 300 | Q3: 0 | R3: 0 | S3: 0 | T3: 0 | U3: 0 | V3: 0 | W3: 0
A4: 3 | B4: 200 | C4: 200 | D4: 0 | E4: 200 | F4: 0 | G4: 200 | H4: 200 | I4: 0 | J4: 0 | K4: 0 | L4: 0 | M4: 0 | N4: 87.5 | P4: 500 | Q4: 0 | R4: 0 | S4: 0 | T4: 0 | U4: 0 | V4: 0 | W4: 0
A5: 4 | B5: 200 | C5: 200 | D5: 0 | E5: 0 | F5: 0 | G5: 200 | H5: 0 | I5: 0 | J5: 200 | K5: 0 | L5: 200 | M5: 200 | N5: 287.5 | P5: 300 | Q5: 0 | R5: 0 | S5: 0 | T5: 0 | U5: 0 | V5: 0 | W5: 0
A6: 5 | B6: 464 | C6: 464 | D6: 400 | E6: 0 | F6: 200 | G6: 664 | H6: 400 | I6: 0 | J6: 264 | K6: 0 | L6: 264 | M6: 264 | N6: 551.5 | P6: 364 | Q6: 0 | R6: 0 | S6: 0 | T6: 0 | U6: 0 | V6: 0 | W6: 0
A7: 6 | B7: 624 | C7: 624 | D7: 300 | E7: 0 | F7: 264 | G7: 888 | H7: 300 | I7: 0 | J7: 588 | K7: 0 | L7: 588 | M7: 588 | N7: 1139.5 | P7: 488 | Q7: 0 | R7: 0 | S7: 0 | T7: 0 | U7: 0 | V7: 0 | W7: 0
A8: 7 | B8: 1060 | C8: 1060 | D8: 500 | E8: 0 | F8: 588 | G8: 1648 | H8: 500 | I8: 0 | J8: 1148 | K8: 0 | L8: 1148 | M8: 1148 | N8: 2287.5 | P8: 1248 | Q8: 0 | R8: 0 | S8: 0 | T8: 0 | U8: 0 | V8: 0 | W8: 0
A9: 8 | B9: 984 | C9: 984 | D9: 300 | E9: 0 | F9: 1148 | G9: 2132 | H9: 300 | I9: 0 | J9: 1832 | K9: 0 | L9: 1832 | M9: 1832 | N9: 4119.5 | P9: 1868 | Q9: 0 | R9: 0 | S9: 0 | T9: 0 | U9: 0 | V9: 0 | W9: 0
A10: 9 | B10: 1080 | C10: 1080 | D10: 364 | E10: 0 | F10: 1832 | G10: 2912 | H10: 364 | I10: 0 | J10: 2548 | K10: 0 | L10: 2548 | M10: 2548 | N10: 6667.5 | P10: 2512 | Q10: 0 | R10: 0 | S10: 0 | T10: 0 | U10: 0 | V10: 0 | W10: 0
A11: 10 | B11: 880 | C11: 880 | D11: 436 | E11: 0 | F11: 2548 | G11: 3428 | H11: 436 | I11: 0 | J11: 2992 | K11: 0 | L11: 2992 | M11: 2992 | N11: 9659.5 | P11: 3028 | Q11: 0 | R11: 0 | S11: 0 | T11: 0 | U11: 0 | V11: 0 | W11: 0
A12: 11 | B12: 948 | C12: 948 | D12: 364 | E12: 0 | F12: 2992 | G12: 3940 | H12: 364 | I12: 0 | J12: 3576 | K12: 0 | L12: 3576 | M12: 3576 | N12: 13235.5 | P12: 3488 | Q12: 0 | R12: 0 | S12: 0 | T12: 0 | U12: 0 | V12: 0 | W12: 0
A13: 12 | B13: 644 | C13: 644 | D13: 488 | E13: 0 | F13: 3576 | G13: 4220 | H13: 488 | I13: 0 | J13: 3732 | K13: 0 | L13: 3732 | M13: 3732 | N13: 16967.5 | P13: 2884 | Q13: 0 | R13: 0 | S13: 0 | T13: 0 | U13: 0 | V13: 0 | W13: 0
... A36: 35 | B36: 0 | C36: 0 | D36: 0 | E36: 11512 | F36: 0 | G36: 0 | H36: 0 | I36: 11512 | J36: 0 | K36: 2878 | L36: 0 | M36: 2878 | N36: 75833.5 | P36: 0 | Q36: 0 | R36: 0 | S36: 0 | T36: 0 | U36: 0 | V36: 0 | W36: 0

Sheet S1_D1_Factory
A1: Week | B1: CustomerDemand | C1: In | D1: Recv | E1: BegInv | F1: BegBacklog | G1: TotalReq | H1: Ship | I1: EndInv | J1: EndBacklog | K1: InvCost | L1: BackCost | M1: WeekCost | N1: CumulativeCost | O1: OrderManual | P1: OrderPlaced | Q1: OrderPipe1 | R1: OrderPipe2 | S1: ShipPipe1 | T1: ShipPipe2 | U1: InventoryPos | V1: TargetLevel | W1: SuggestedOrder
A2: 1 | B2: 0 | C2: 0 | D2: 50 | E2: 100 | F2: 0 | G2: 0 | H2: 0 | I2: 150 | J2: 0 | K2: 37.5 | L2: 0 | M2: 37.5 | N2: 37.5 | P2: 600 | Q2: 0 | R2: 0 | S2: 0 | T2: 0 | U2: 0 | V2: 0 | W2: 0
A3: 2 | B3: 0 | C3: 0 | D3: 50 | E3: 150 | F3: 0 | G3: 0 | H3: 0 | I3: 200 | J3: 0 | K3: 50 | L3: 0 | M3: 50 | N3: 87.5 | P3: 0 | Q3: 0 | R3: 0 | S3: 0 | T3: 0 | U3: 0 | V3: 0 | W3: 0
A4: 3 | B4: 400 | C4: 400 | D4: 600 | E4: 200 | F4: 0 | G4: 400 | H4: 400 | I4: 400 | J4: 0 | K4: 100 | L4: 0 | M4: 100 | N4: 187.5 | P4: 400 | Q4: 0 | R4: 0 | S4: 0 | T4: 0 | U4: 0 | V4: 0 | W4: 0
A5: 4 | B5: 300 | C5: 300 | D5: 0 | E5: 400 | F5: 0 | G5: 300 | H5: 300 | I5: 100 | J5: 0 | K5: 25 | L5: 0 | M5: 25 | N5: 212.5 | P5: 300 | Q5: 0 | R5: 0 | S5: 0 | T5: 0 | U5: 0 | V5: 0 | W5: 0
A6: 5 | B6: 500 | C6: 500 | D6: 400 | E6: 100 | F6: 0 | G6: 500 | H6: 500 | I6: 0 | J6: 0 | K6: 0 | L6: 0 | M6: 0 | N6: 212.5 | P6: 500 | Q6: 0 | R6: 0 | S6: 0 | T6: 0 | U6: 0 | V6: 0 | W6: 0
A7: 6 | B7: 300 | C7: 300 | D7: 300 | E7: 0 | F7: 0 | G7: 300 | H7: 300 | I7: 0 | J7: 0 | K7: 0 | L7: 0 | M7: 0 | N7: 212.5 | P7: 300 | Q7: 0 | R7: 0 | S7: 0 | T7: 0 | U7: 0 | V7: 0 | W7: 0
A8: 7 | B8: 364 | C8: 364 | D8: 500 | E8: 0 | F8: 0 | G8: 364 | H8: 364 | I8: 136 | J8: 0 | K8: 34 | L8: 0 | M8: 34 | N8: 246.5 | P8: 364 | Q8: 0 | R8: 0 | S8: 0 | T8: 0 | U8: 0 | V8: 0 | W8: 0
A9: 8 | B9: 488 | C9: 488 | D9: 300 | E9: 136 | F9: 0 | G9: 488 | H9: 436 | I9: 0 | J9: 52 | K9: 0 | L9: 52 | M9: 52 | N9: 298.5 | P9: 488 | Q9: 0 | R9: 0 | S9: 0 | T9: 0 | U9: 0 | V9: 0 | W9: 0
A10: 9 | B10: 1248 | C10: 1248 | D10: 364 | E10: 0 | F10: 52 | G10: 1300 | H10: 364 | I10: 0 | J10: 936 | K10: 0 | L10: 936 | M10: 936 | N10: 1234.5 | P10: 1248 | Q10: 0 | R10: 0 | S10: 0 | T10: 0 | U10: 0 | V10: 0 | W10: 0
A11: 10 | B11: 1868 | C11: 1868 | D11: 488 | E11: 0 | F11: 936 | G11: 2804 | H11: 488 | I11: 0 | J11: 2316 | K11: 0 | L11: 2316 | M11: 2316 | N11: 3550.5 | P11: 1868 | Q11: 0 | R11: 0 | S11: 0 | T11: 0 | U11: 0 | V11: 0 | W11: 0
A12: 11 | B12: 2512 | C12: 2512 | D12: 1248 | E12: 0 | F12: 2316 | G12: 4828 | H12: 1248 | I12: 0 | J12: 3580 | K12: 0 | L12: 3580 | M12: 3580 | N12: 7130.5 | P12: 2512 | Q12: 0 | R12: 0 | S12: 0 | T12: 0 | U12: 0 | V12: 0 | W12: 0
A13: 12 | B13: 3028 | C13: 3028 | D13: 1868 | E13: 0 | F13: 3580 | G13: 6608 | H13: 1868 | I13: 0 | J13: 4740 | K13: 0 | L13: 4740 | M13: 4740 | N13: 11870.5 | P13: 3028 | Q13: 0 | R13: 0 | S13: 0 | T13: 0 | U13: 0 | V13: 0 | W13: 0
... A36: 35 | B36: 0 | C36: 0 | D36: 0 | E36: 400 | F36: 0 | G36: 0 | H36: 0 | I36: 400 | J36: 0 | K36: 100 | L36: 0 | M36: 100 | N36: 28790.5 | P36: 0 | Q36: 0 | R36: 0 | S36: 0 | T36: 0 | U36: 0 | V36: 0 | W36: 0

Sheet S1_D2_Retailer
A1: Week | B1: CustomerDemand | C1: In | D1: Recv | E1: BegInv | F1: BegBacklog | G1: TotalReq | H1: Ship | I1: EndInv | J1: EndBacklog | K1: InvCost | L1: BackCost | M1: WeekCost | N1: CumulativeCost | O1: OrderManual | P1: OrderPlaced | Q1: OrderPipe1 | R1: OrderPipe2 | S1: ShipPipe1 | T1: ShipPipe2 | U1: InventoryPos | V1: TargetLevel | W1: SuggestedOrder
A2: 1 | B2: 100 | C2: 100 | D2: 50 | E2: 100 | F2: 0 | G2: 100 | H2: 100 | I2: 50 | J2: 0 | K2: 12.5 | L2: 0 | M2: 12.5 | N2: 12.5 | P2: 300 | Q2: 0 | R2: 0 | S2: 0 | T2: 0 | U2: 0 | V2: 0 | W2: 0
A3: 2 | B3: 100 | C3: 100 | D3: 50 | E3: 50 | F3: 0 | G3: 100 | H3: 100 | I3: 0 | J3: 0 | K3: 0 | L3: 0 | M3: 0 | N3: 12.5 | P3: 400 | Q3: 0 | R3: 0 | S3: 0 | T3: 0 | U3: 0 | V3: 0 | W3: 0
A4: 3 | B4: 100 | C4: 100 | D4: 0 | E4: 0 | F4: 0 | G4: 100 | H4: 0 | I4: 0 | J4: 100 | K4: 0 | L4: 100 | M4: 100 | N4: 112.5 | P4: 500 | Q4: 0 | R4: 0 | S4: 0 | T4: 0 | U4: 0 | V4: 0 | W4: 0
A5: 4 | B5: 100 | C5: 100 | D5: 0 | E5: 0 | F5: 100 | G5: 200 | H5: 0 | I5: 0 | J5: 200 | K5: 0 | L5: 200 | M5: 200 | N5: 312.5 | P5: 400 | Q5: 0 | R5: 0 | S5: 0 | T5: 0 | U5: 0 | V5: 0 | W5: 0
A6: 5 | B6: 100 | C6: 100 | D6: 200 | E6: 0 | F6: 200 | G6: 300 | H6: 200 | I6: 0 | J6: 100 | K6: 0 | L6: 100 | M6: 100 | N6: 412.5 | P6: 500 | Q6: 0 | R6: 0 | S6: 0 | T6: 0 | U6: 0 | V6: 0 | W6: 0
A7: 6 | B7: 100 | C7: 100 | D7: 0 | E7: 0 | F7: 100 | G7: 200 | H7: 0 | I7: 0 | J7: 200 | K7: 0 | L7: 200 | M7: 200 | N7: 612.5 | P7: 400 | Q7: 0 | R7: 0 | S7: 0 | T7: 0 | U7: 0 | V7: 0 | W7: 0
A8: 7 | B8: 100 | C8: 100 | D8: 200 | E8: 0 | F8: 200 | G8: 300 | H8: 200 | I8: 0 | J8: 100 | K8: 0 | L8: 100 | M8: 100 | N8: 712.5 | P8: 500 | Q8: 0 | R8: 0 | S8: 0 | T8: 0 | U8: 0 | V8: 0 | W8: 0
A9: 8 | B9: 100 | C9: 100 | D9: 0 | E9: 0 | F9: 100 | G9: 200 | H9: 0 | I9: 0 | J9: 200 | K9: 0 | L9: 200 | M9: 200 | N9: 912.5 | P9: 200 | Q9: 0 | R9: 0 | S9: 0 | T9: 0 | U9: 0 | V9: 0 | W9: 0
A10: 9 | B10: 100 | C10: 100 | D10: 400 | E10: 0 | F10: 200 | G10: 300 | H10: 300 | I10: 100 | J10: 0 | K10: 25 | L10: 0 | M10: 25 | N10: 937.5 | P10: 0 | Q10: 0 | R10: 0 | S10: 0 | T10: 0 | U10: 0 | V10: 0 | W10: 0
A11: 10 | B11: 100 | C11: 100 | D11: 300 | E11: 100 | F11: 0 | G11: 100 | H11: 100 | I11: 300 | J11: 0 | K11: 75 | L11: 0 | M11: 75 | N11: 1012.5 | P11: 0 | Q11: 0 | R11: 0 | S11: 0 | T11: 0 | U11: 0 | V11: 0 | W11: 0
A12: 11 | B12: 100 | C12: 100 | D12: 500 | E12: 300 | F12: 0 | G12: 100 | H12: 100 | I12: 700 | J12: 0 | K12: 175 | L12: 0 | M12: 175 | N12: 1187.5 | P12: 0 | Q12: 0 | R12: 0 | S12: 0 | T12: 0 | U12: 0 | V12: 0 | W12: 0
A13: 12 | B13: 100 | C13: 100 | D13: 300 | E13: 700 | F13: 0 | G13: 100 | H13: 100 | I13: 900 | J13: 0 | K13: 225 | L13: 0 | M13: 225 | N13: 1412.5 | P13: 0 | Q13: 0 | R13: 0 | S13: 0 | T13: 0 | U13: 0 | V13: 0 | W13: 0
... A36: 35 | B36: 100 | C36: 100 | D36: 100 | E36: 0 | F36: 0 | G36: 100 | H36: 100 | I36: 0 | J36: 0 | K36: 0 | L36: 0 | M36: 0 | N36: 6812.5 | P36: 200 | Q36: 0 | R36: 0 | S36: 0 | T36: 0 | U36: 0 | V36: 0 | W36: 0

Sheet S1_D2_Wholesaler
A1: Week | B1: CustomerDemand | C1: In | D1: Recv | E1: BegInv | F1: BegBacklog | G1: TotalReq | H1: Ship | I1: EndInv | J1: EndBacklog | K1: InvCost | L1: BackCost | M1: WeekCost | N1: CumulativeCost | O1: OrderManual | P1: OrderPlaced | Q1: OrderPipe1 | R1: OrderPipe2 | S1: ShipPipe1 | T1: ShipPipe2 | U1: InventoryPos | V1: TargetLevel | W1: SuggestedOrder
A2: 1 | B2: 0 | C2: 0 | D2: 50 | E2: 100 | F2: 0 | G2: 0 | H2: 0 | I2: 150 | J2: 0 | K2: 37.5 | L2: 0 | M2: 37.5 | N2: 37.5 | P2: 200 | Q2: 0 | R2: 0 | S2: 0 | T2: 0 | U2: 0 | V2: 0 | W2: 0
A3: 2 | B3: 0 | C3: 0 | D3: 50 | E3: 150 | F3: 0 | G3: 0 | H3: 0 | I3: 200 | J3: 0 | K3: 50 | L3: 0 | M3: 50 | N3: 87.5 | P3: 200 | Q3: 0 | R3: 0 | S3: 0 | T3: 0 | U3: 0 | V3: 0 | W3: 0
A4: 3 | B4: 300 | C4: 300 | D4: 0 | E4: 200 | F4: 0 | G4: 300 | H4: 200 | I4: 0 | J4: 100 | K4: 0 | L4: 100 | M4: 100 | N4: 187.5 | P4: 500 | Q4: 0 | R4: 0 | S4: 0 | T4: 0 | U4: 0 | V4: 0 | W4: 0
A5: 4 | B5: 400 | C5: 400 | D5: 0 | E5: 0 | F5: 100 | G5: 500 | H5: 0 | I5: 0 | J5: 500 | K5: 0 | L5: 500 | M5: 500 | N5: 687.5 | P5: 700 | Q5: 0 | R5: 0 | S5: 0 | T5: 0 | U5: 0 | V5: 0 | W5: 0
A6: 5 | B6: 500 | C6: 500 | D6: 200 | E6: 0 | F6: 500 | G6: 1000 | H6: 200 | I6: 0 | J6: 800 | K6: 0 | L6: 800 | M6: 800 | N6: 1487.5 | P6: 1200 | Q6: 0 | R6: 0 | S6: 0 | T6: 0 | U6: 0 | V6: 0 | W6: 0
A7: 6 | B7: 400 | C7: 400 | D7: 0 | E7: 0 | F7: 800 | G7: 1200 | H7: 0 | I7: 0 | J7: 1200 | K7: 0 | L7: 1200 | M7: 1200 | N7: 2687.5 | P7: 1200 | Q7: 0 | R7: 0 | S7: 0 | T7: 0 | U7: 0 | V7: 0 | W7: 0
A8: 7 | B8: 500 | C8: 500 | D8: 400 | E8: 0 | F8: 1200 | G8: 1700 | H8: 400 | I8: 0 | J8: 1300 | K8: 0 | L8: 1300 | M8: 1300 | N8: 3987.5 | P8: 1400 | Q8: 0 | R8: 0 | S8: 0 | T8: 0 | U8: 0 | V8: 0 | W8: 0
A9: 8 | B9: 400 | C9: 400 | D9: 300 | E9: 0 | F9: 1300 | G9: 1700 | H9: 300 | I9: 0 | J9: 1400 | K9: 0 | L9: 1400 | M9: 1400 | N9: 5387.5 | P9: 1300 | Q9: 0 | R9: 0 | S9: 0 | T9: 0 | U9: 0 | V9: 0 | W9: 0
A10: 9 | B10: 500 | C10: 500 | D10: 500 | E10: 0 | F10: 1400 | G10: 1900 | H10: 500 | I10: 0 | J10: 1400 | K10: 0 | L10: 1400 | M10: 1400 | N10: 6787.5 | P10: 1500 | Q10: 0 | R10: 0 | S10: 0 | T10: 0 | U10: 0 | V10: 0 | W10: 0
A11: 10 | B11: 200 | C11: 200 | D11: 300 | E11: 0 | F11: 1400 | G11: 1600 | H11: 300 | I11: 0 | J11: 1300 | K11: 0 | L11: 1300 | M11: 1300 | N11: 8087.5 | P11: 1300 | Q11: 0 | R11: 0 | S11: 0 | T11: 0 | U11: 0 | V11: 0 | W11: 0
A12: 11 | B12: 0 | C12: 0 | D12: 400 | E12: 0 | F12: 1300 | G12: 1300 | H12: 400 | I12: 0 | J12: 900 | K12: 0 | L12: 900 | M12: 900 | N12: 8987.5 | P12: 900 | Q12: 0 | R12: 0 | S12: 0 | T12: 0 | U12: 0 | V12: 0 | W12: 0
A13: 12 | B13: 0 | C13: 0 | D13: 400 | E13: 0 | F13: 900 | G13: 900 | H13: 400 | I13: 0 | J13: 500 | K13: 0 | L13: 500 | M13: 500 | N13: 9487.5 | P13: 500 | Q13: 0 | R13: 0 | S13: 0 | T13: 0 | U13: 0 | V13: 0 | W13: 0
... A36: 35 | B36: 300 | C36: 300 | D36: 0 | E36: 7600 | F36: 0 | G36: 300 | H36: 300 | I36: 7300 | J36: 0 | K36: 1825 | L36: 0 | M36: 1825 | N36: 48487.5 | P36: 0 | Q36: 0 | R36: 0 | S36: 0 | T36: 0 | U36: 0 | V36: 0 | W36: 0

Sheet S1_D2_Distributor
A1: Week | B1: CustomerDemand | C1: In | D1: Recv | E1: BegInv | F1: BegBacklog | G1: TotalReq | H1: Ship | I1: EndInv | J1: EndBacklog | K1: InvCost | L1: BackCost | M1: WeekCost | N1: CumulativeCost | O1: OrderManual | P1: OrderPlaced | Q1: OrderPipe1 | R1: OrderPipe2 | S1: ShipPipe1 | T1: ShipPipe2 | U1: InventoryPos | V1: TargetLevel | W1: SuggestedOrder
A2: 1 | B2: 0 | C2: 0 | D2: 50 | E2: 100 | F2: 0 | G2: 0 | H2: 0 | I2: 150 | J2: 0 | K2: 37.5 | L2: 0 | M2: 37.5 | N2: 37.5 | P2: 400 | Q2: 0 | R2: 0 | S2: 0 | T2: 0 | U2: 0 | V2: 0 | W2: 0
A3: 2 | B3: 0 | C3: 0 | D3: 50 | E3: 150 | F3: 0 | G3: 0 | H3: 0 | I3: 200 | J3: 0 | K3: 50 | L3: 0 | M3: 50 | N3: 87.5 | P3: 300 | Q3: 0 | R3: 0 | S3: 0 | T3: 0 | U3: 0 | V3: 0 | W3: 0
A4: 3 | B4: 200 | C4: 200 | D4: 0 | E4: 200 | F4: 0 | G4: 200 | H4: 200 | I4: 0 | J4: 0 | K4: 0 | L4: 0 | M4: 0 | N4: 87.5 | P4: 500 | Q4: 0 | R4: 0 | S4: 0 | T4: 0 | U4: 0 | V4: 0 | W4: 0
A5: 4 | B5: 200 | C5: 200 | D5: 0 | E5: 0 | F5: 0 | G5: 200 | H5: 0 | I5: 0 | J5: 200 | K5: 0 | L5: 200 | M5: 200 | N5: 287.5 | P5: 300 | Q5: 0 | R5: 0 | S5: 0 | T5: 0 | U5: 0 | V5: 0 | W5: 0
A6: 5 | B6: 500 | C6: 500 | D6: 400 | E6: 0 | F6: 200 | G6: 700 | H6: 400 | I6: 0 | J6: 300 | K6: 0 | L6: 300 | M6: 300 | N6: 587.5 | P6: 400 | Q6: 0 | R6: 0 | S6: 0 | T6: 0 | U6: 0 | V6: 0 | W6: 0
A7: 6 | B7: 700 | C7: 700 | D7: 300 | E7: 0 | F7: 300 | G7: 1000 | H7: 300 | I7: 0 | J7: 700 | K7: 0 | L7: 700 | M7: 700 | N7: 1287.5 | P7: 600 | Q7: 0 | R7: 0 | S7: 0 | T7: 0 | U7: 0 | V7: 0 | W7: 0
A8: 7 | B8: 1200 | C8: 1200 | D8: 500 | E8: 0 | F8: 700 | G8: 1900 | H8: 500 | I8: 0 | J8: 1400 | K8: 0 | L8: 1400 | M8: 1400 | N8: 2687.5 | P8: 1500 | Q8: 0 | R8: 0 | S8: 0 | T8: 0 | U8: 0 | V8: 0 | W8: 0
A9: 8 | B9: 1200 | C9: 1200 | D9: 300 | E9: 0 | F9: 1400 | G9: 2600 | H9: 300 | I9: 0 | J9: 2300 | K9: 0 | L9: 2300 | M9: 2300 | N9: 4987.5 | P9: 2300 | Q9: 0 | R9: 0 | S9: 0 | T9: 0 | U9: 0 | V9: 0 | W9: 0
A10: 9 | B10: 1400 | C10: 1400 | D10: 400 | E10: 0 | F10: 2300 | G10: 3700 | H10: 400 | I10: 0 | J10: 3300 | K10: 0 | L10: 3300 | M10: 3300 | N10: 8287.5 | P10: 3300 | Q10: 0 | R10: 0 | S10: 0 | T10: 0 | U10: 0 | V10: 0 | W10: 0
A11: 10 | B11: 1300 | C11: 1300 | D11: 400 | E11: 0 | F11: 3300 | G11: 4600 | H11: 400 | I11: 0 | J11: 4200 | K11: 0 | L11: 4200 | M11: 4200 | N11: 12487.5 | P11: 4200 | Q11: 0 | R11: 0 | S11: 0 | T11: 0 | U11: 0 | V11: 0 | W11: 0
A12: 11 | B12: 1500 | C12: 1500 | D12: 400 | E12: 0 | F12: 4200 | G12: 5700 | H12: 400 | I12: 0 | J12: 5300 | K12: 0 | L12: 5300 | M12: 5300 | N12: 17787.5 | P12: 5100 | Q12: 0 | R12: 0 | S12: 0 | T12: 0 | U12: 0 | V12: 0 | W12: 0
A13: 12 | B13: 1300 | C13: 1300 | D13: 600 | E13: 0 | F13: 5300 | G13: 6600 | H13: 600 | I13: 0 | J13: 6000 | K13: 0 | L13: 6000 | M13: 6000 | N13: 23787.5 | P13: 4900 | Q13: 0 | R13: 0 | S13: 0 | T13: 0 | U13: 0 | V13: 0 | W13: 0
... A36: 35 | B36: 0 | C36: 0 | D36: 0 | E36: 17300 | F36: 0 | G36: 0 | H36: 0 | I36: 17300 | J36: 0 | K36: 4325 | L36: 0 | M36: 4325 | N36: 113312.5 | P36: 0 | Q36: 0 | R36: 0 | S36: 0 | T36: 0 | U36: 0 | V36: 0 | W36: 0

Sheet S1_D2_Factory
A1: Week | B1: CustomerDemand | C1: In | D1: Recv | E1: BegInv | F1: BegBacklog | G1: TotalReq | H1: Ship | I1: EndInv | J1: EndBacklog | K1: InvCost | L1: BackCost | M1: WeekCost | N1: CumulativeCost | O1: OrderManual | P1: OrderPlaced | Q1: OrderPipe1 | R1: OrderPipe2 | S1: ShipPipe1 | T1: ShipPipe2 | U1: InventoryPos | V1: TargetLevel | W1: SuggestedOrder
A2: 1 | B2: 0 | C2: 0 | D2: 50 | E2: 100 | F2: 0 | G2: 0 | H2: 0 | I2: 150 | J2: 0 | K2: 37.5 | L2: 0 | M2: 37.5 | N2: 37.5 | P2: 600 | Q2: 0 | R2: 0 | S2: 0 | T2: 0 | U2: 0 | V2: 0 | W2: 0
A3: 2 | B3: 0 | C3: 0 | D3: 50 | E3: 150 | F3: 0 | G3: 0 | H3: 0 | I3: 200 | J3: 0 | K3: 50 | L3: 0 | M3: 50 | N3: 87.5 | P3: 0 | Q3: 0 | R3: 0 | S3: 0 | T3: 0 | U3: 0 | V3: 0 | W3: 0
A4: 3 | B4: 400 | C4: 400 | D4: 600 | E4: 200 | F4: 0 | G4: 400 | H4: 400 | I4: 400 | J4: 0 | K4: 100 | L4: 0 | M4: 100 | N4: 187.5 | P4: 400 | Q4: 0 | R4: 0 | S4: 0 | T4: 0 | U4: 0 | V4: 0 | W4: 0
A5: 4 | B5: 300 | C5: 300 | D5: 0 | E5: 400 | F5: 0 | G5: 300 | H5: 300 | I5: 100 | J5: 0 | K5: 25 | L5: 0 | M5: 25 | N5: 212.5 | P5: 300 | Q5: 0 | R5: 0 | S5: 0 | T5: 0 | U5: 0 | V5: 0 | W5: 0
A6: 5 | B6: 500 | C6: 500 | D6: 400 | E6: 100 | F6: 0 | G6: 500 | H6: 500 | I6: 0 | J6: 0 | K6: 0 | L6: 0 | M6: 0 | N6: 212.5 | P6: 500 | Q6: 0 | R6: 0 | S6: 0 | T6: 0 | U6: 0 | V6: 0 | W6: 0
A7: 6 | B7: 300 | C7: 300 | D7: 300 | E7: 0 | F7: 0 | G7: 300 | H7: 300 | I7: 0 | J7: 0 | K7: 0 | L7: 0 | M7: 0 | N7: 212.5 | P7: 300 | Q7: 0 | R7: 0 | S7: 0 | T7: 0 | U7: 0 | V7: 0 | W7: 0
A8: 7 | B8: 400 | C8: 400 | D8: 500 | E8: 0 | F8: 0 | G8: 400 | H8: 400 | I8: 100 | J8: 0 | K8: 25 | L8: 0 | M8: 25 | N8: 237.5 | P8: 400 | Q8: 0 | R8: 0 | S8: 0 | T8: 0 | U8: 0 | V8: 0 | W8: 0
A9: 8 | B9: 600 | C9: 600 | D9: 300 | E9: 100 | F9: 0 | G9: 600 | H9: 400 | I9: 0 | J9: 200 | K9: 0 | L9: 200 | M9: 200 | N9: 437.5 | P9: 600 | Q9: 0 | R9: 0 | S9: 0 | T9: 0 | U9: 0 | V9: 0 | W9: 0
A10: 9 | B10: 1500 | C10: 1500 | D10: 400 | E10: 0 | F10: 200 | G10: 1700 | H10: 400 | I10: 0 | J10: 1300 | K10: 0 | L10: 1300 | M10: 1300 | N10: 1737.5 | P10: 1500 | Q10: 0 | R10: 0 | S10: 0 | T10: 0 | U10: 0 | V10: 0 | W10: 0
A11: 10 | B11: 2300 | C11: 2300 | D11: 600 | E11: 0 | F11: 1300 | G11: 3600 | H11: 600 | I11: 0 | J11: 3000 | K11: 0 | L11: 3000 | M11: 3000 | N11: 4737.5 | P11: 2300 | Q11: 0 | R11: 0 | S11: 0 | T11: 0 | U11: 0 | V11: 0 | W11: 0
A12: 11 | B12: 3300 | C12: 3300 | D12: 1500 | E12: 0 | F12: 3000 | G12: 6300 | H12: 1500 | I12: 0 | J12: 4800 | K12: 0 | L12: 4800 | M12: 4800 | N12: 9537.5 | P12: 3300 | Q12: 0 | R12: 0 | S12: 0 | T12: 0 | U12: 0 | V12: 0 | W12: 0
A13: 12 | B13: 4200 | C13: 4200 | D13: 2300 | E13: 0 | F13: 4800 | G13: 9000 | H13: 2300 | I13: 0 | J13: 6700 | K13: 0 | L13: 6700 | M13: 6700 | N13: 16237.5 | P13: 4200 | Q13: 0 | R13: 0 | S13: 0 | T13: 0 | U13: 0 | V13: 0 | W13: 0
... A36: 35 | B36: 0 | C36: 0 | D36: 0 | E36: 400 | F36: 0 | G36: 0 | H36: 0 | I36: 400 | J36: 0 | K36: 100 | L36: 0 | M36: 100 | N36: 46737.5 | P36: 0 | Q36: 0 | R36: 0 | S36: 0 | T36: 0 | U36: 0 | V36: 0 | W36: 0

Sheet S1_D3_Retailer
A1: Week | B1: CustomerDemand | C1: In | D1: Recv | E1: BegInv | F1: BegBacklog | G1: TotalReq | H1: Ship | I1: EndInv | J1: EndBacklog | K1: InvCost | L1: BackCost | M1: WeekCost | N1: CumulativeCost | O1: OrderManual | P1: OrderPlaced | Q1: OrderPipe1 | R1: OrderPipe2 | S1: ShipPipe1 | T1: ShipPipe2 | U1: InventoryPos | V1: TargetLevel | W1: SuggestedOrder
A2: 1 | B2: 91 | C2: 91 | D2: 50 | E2: 100 | F2: 0 | G2: 91 | H2: 91 | I2: 59 | J2: 0 | K2: 14.75 | L2: 0 | M2: 14.75 | N2: 14.75 | P2: 291 | Q2: 0 | R2: 0 | S2: 0 | T2: 0 | U2: 0 | V2: 0 | W2: 0
A3: 2 | B3: 139 | C3: 139 | D3: 50 | E3: 59 | F3: 0 | G3: 139 | H3: 109 | I3: 0 | J3: 30 | K3: 0 | L3: 30 | M3: 30 | N3: 44.75 | P3: 430 | Q3: 0 | R3: 0 | S3: 0 | T3: 0 | U3: 0 | V3: 0 | W3: 0
A4: 3 | B4: 109 | C4: 109 | D4: 0 | E4: 0 | F4: 30 | G4: 139 | H4: 0 | I4: 0 | J4: 139 | K4: 0 | L4: 139 | M4: 139 | N4: 183.75 | P4: 539 | Q4: 0 | R4: 0 | S4: 0 | T4: 0 | U4: 0 | V4: 0 | W4: 0
A5: 4 | B5: 127 | C5: 127 | D5: 0 | E5: 0 | F5: 139 | G5: 266 | H5: 0 | I5: 0 | J5: 266 | K5: 0 | L5: 266 | M5: 266 | N5: 449.75 | P5: 466 | Q5: 0 | R5: 0 | S5: 0 | T5: 0 | U5: 0 | V5: 0 | W5: 0
A6: 5 | B6: 103 | C6: 103 | D6: 200 | E6: 0 | F6: 266 | G6: 369 | H6: 200 | I6: 0 | J6: 169 | K6: 0 | L6: 169 | M6: 169 | N6: 618.75 | P6: 569 | Q6: 0 | R6: 0 | S6: 0 | T6: 0 | U6: 0 | V6: 0 | W6: 0
A7: 6 | B7: 151 | C7: 151 | D7: 0 | E7: 0 | F7: 169 | G7: 320 | H7: 0 | I7: 0 | J7: 320 | K7: 0 | L7: 320 | M7: 320 | N7: 938.75 | P7: 520 | Q7: 0 | R7: 0 | S7: 0 | T7: 0 | U7: 0 | V7: 0 | W7: 0
A8: 7 | B8: 97 | C8: 97 | D8: 200 | E8: 0 | F8: 320 | G8: 417 | H8: 200 | I8: 0 | J8: 217 | K8: 0 | L8: 217 | M8: 217 | N8: 1155.75 | P8: 617 | Q8: 0 | R8: 0 | S8: 0 | T8: 0 | U8: 0 | V8: 0 | W8: 0
A9: 8 | B9: 133 | C9: 133 | D9: 0 | E9: 0 | F9: 217 | G9: 350 | H9: 0 | I9: 0 | J9: 350 | K9: 0 | L9: 350 | M9: 350 | N9: 1505.75 | P9: 350 | Q9: 0 | R9: 0 | S9: 0 | T9: 0 | U9: 0 | V9: 0 | W9: 0
A10: 9 | B10: 115 | C10: 115 | D10: 400 | E10: 0 | F10: 350 | G10: 465 | H10: 400 | I10: 0 | J10: 65 | K10: 0 | L10: 65 | M10: 65 | N10: 1570.75 | P10: 165 | Q10: 0 | R10: 0 | S10: 0 | T10: 0 | U10: 0 | V10: 0 | W10: 0
A11: 10 | B11: 121 | C11: 121 | D11: 300 | E11: 0 | F11: 65 | G11: 186 | H11: 186 | I11: 114 | J11: 0 | K11: 28.5 | L11: 0 | M11: 28.5 | N11: 1599.25 | P11: 0 | Q11: 0 | R11: 0 | S11: 0 | T11: 0 | U11: 0 | V11: 0 | W11: 0
A12: 11 | B12: 85 | C12: 85 | D12: 500 | E12: 114 | F12: 0 | G12: 85 | H12: 85 | I12: 529 | J12: 0 | K12: 132.25 | L12: 0 | M12: 132.25 | N12: 1731.5 | P12: 0 | Q12: 0 | R12: 0 | S12: 0 | T12: 0 | U12: 0 | V12: 0 | W12: 0
A13: 12 | B13: 145 | C13: 145 | D13: 300 | E13: 529 | F13: 0 | G13: 145 | H13: 145 | I13: 684 | J13: 0 | K13: 171 | L13: 0 | M13: 171 | N13: 1902.5 | P13: 0 | Q13: 0 | R13: 0 | S13: 0 | T13: 0 | U13: 0 | V13: 0 | W13: 0
... A36: 35 | B36: 67 | C36: 67 | D36: 0 | E36: 189 | F36: 0 | G36: 67 | H36: 67 | I36: 122 | J36: 0 | K36: 30.5 | L36: 0 | M36: 30.5 | N36: 8668.5 | P36: 278 | Q36: 0 | R36: 0 | S36: 0 | T36: 0 | U36: 0 | V36: 0 | W36: 0

Sheet S1_D3_Wholesaler
A1: Week | B1: CustomerDemand | C1: In | D1: Recv | E1: BegInv | F1: BegBacklog | G1: TotalReq | H1: Ship | I1: EndInv | J1: EndBacklog | K1: InvCost | L1: BackCost | M1: WeekCost | N1: CumulativeCost | O1: OrderManual | P1: OrderPlaced | Q1: OrderPipe1 | R1: OrderPipe2 | S1: ShipPipe1 | T1: ShipPipe2 | U1: InventoryPos | V1: TargetLevel | W1: SuggestedOrder
A2: 1 | B2: 0 | C2: 0 | D2: 50 | E2: 100 | F2: 0 | G2: 0 | H2: 0 | I2: 150 | J2: 0 | K2: 37.5 | L2: 0 | M2: 37.5 | N2: 37.5 | P2: 200 | Q2: 0 | R2: 0 | S2: 0 | T2: 0 | U2: 0 | V2: 0 | W2: 0
A3: 2 | B3: 0 | C3: 0 | D3: 50 | E3: 150 | F3: 0 | G3: 0 | H3: 0 | I3: 200 | J3: 0 | K3: 50 | L3: 0 | M3: 50 | N3: 87.5 | P3: 200 | Q3: 0 | R3: 0 | S3: 0 | T3: 0 | U3: 0 | V3: 0 | W3: 0
A4: 3 | B4: 291 | C4: 291 | D4: 0 | E4: 200 | F4: 0 | G4: 291 | H4: 200 | I4: 0 | J4: 91 | K4: 0 | L4: 91 | M4: 91 | N4: 178.5 | P4: 491 | Q4: 0 | R4: 0 | S4: 0 | T4: 0 | U4: 0 | V4: 0 | W4: 0
A5: 4 | B5: 430 | C5: 430 | D5: 0 | E5: 0 | F5: 91 | G5: 521 | H5: 0 | I5: 0 | J5: 521 | K5: 0 | L5: 521 | M5: 521 | N5: 699.5 | P5: 721 | Q5: 0 | R5: 0 | S5: 0 | T5: 0 | U5: 0 | V5: 0 | W5: 0
A6: 5 | B6: 539 | C6: 539 | D6: 200 | E6: 0 | F6: 521 | G6: 1060 | H6: 200 | I6: 0 | J6: 860 | K6: 0 | L6: 860 | M6: 860 | N6: 1559.5 | P6: 1260 | Q6: 0 | R6: 0 | S6: 0 | T6: 0 | U6: 0 | V6: 0 | W6: 0
A7: 6 | B7: 466 | C7: 466 | D7: 0 | E7: 0 | F7: 860 | G7: 1326 | H7: 0 | I7: 0 | J7: 1326 | K7: 0 | L7: 1326 | M7: 1326 | N7: 2885.5 | P7: 1326 | Q7: 0 | R7: 0 | S7: 0 | T7: 0 | U7: 0 | V7: 0 | W7: 0
A8: 7 | B8: 569 | C8: 569 | D8: 400 | E8: 0 | F8: 1326 | G8: 1895 | H8: 400 | I8: 0 | J8: 1495 | K8: 0 | L8: 1495 | M8: 1495 | N8: 4380.5 | P8: 1595 | Q8: 0 | R8: 0 | S8: 0 | T8: 0 | U8: 0 | V8: 0 | W8: 0
A9: 8 | B9: 520 | C9: 520 | D9: 300 | E9: 0 | F9: 1495 | G9: 2015 | H9: 300 | I9: 0 | J9: 1715 | K9: 0 | L9: 1715 | M9: 1715 | N9: 6095.5 | P9: 1615 | Q9: 0 | R9: 0 | S9: 0 | T9: 0 | U9: 0 | V9: 0 | W9: 0
A10: 9 | B10: 617 | C10: 617 | D10: 500 | E10: 0 | F10: 1715 | G10: 2332 | H10: 500 | I10: 0 | J10: 1832 | K10: 0 | L10: 1832 | M10: 1832 | N10: 7927.5 | P10: 1932 | Q10: 0 | R10: 0 | S10: 0 | T10: 0 | U10: 0 | V10: 0 | W10: 0
A11: 10 | B11: 350 | C11: 350 | D11: 300 | E11: 0 | F11: 1832 | G11: 2182 | H11: 300 | I11: 0 | J11: 1882 | K11: 0 | L11: 1882 | M11: 1882 | N11: 9809.5 | P11: 1891 | Q11: 0 | R11: 0 | S11: 0 | T11: 0 | U11: 0 | V11: 0 | W11: 0
A12: 11 | B12: 165 | C12: 165 | D12: 391 | E12: 0 | F12: 1882 | G12: 2047 | H12: 391 | I12: 0 | J12: 1656 | K12: 0 | L12: 1656 | M12: 1656 | N12: 11465.5 | P12: 1647 | Q12: 0 | R12: 0 | S12: 0 | T12: 0 | U12: 0 | V12: 0 | W12: 0
A13: 12 | B13: 0 | C13: 0 | D13: 409 | E13: 0 | F13: 1656 | G13: 1656 | H13: 409 | I13: 0 | J13: 1247 | K13: 0 | L13: 1247 | M13: 1247 | N13: 12712.5 | P13: 1256 | Q13: 0 | R13: 0 | S13: 0 | T13: 0 | U13: 0 | V13: 0 | W13: 0
... A36: 35 | B36: 88 | C36: 88 | D36: 0 | E36: 11031 | F36: 0 | G36: 88 | H36: 88 | I36: 10943 | J36: 0 | K36: 2735.75 | L36: 0 | M36: 2735.75 | N36: 66602.75 | P36: 0 | Q36: 0 | R36: 0 | S36: 0 | T36: 0 | U36: 0 | V36: 0 | W36: 0

Sheet S1_D3_Distributor
A1: Week | B1: CustomerDemand | C1: In | D1: Recv | E1: BegInv | F1: BegBacklog | G1: TotalReq | H1: Ship | I1: EndInv | J1: EndBacklog | K1: InvCost | L1: BackCost | M1: WeekCost | N1: CumulativeCost | O1: OrderManual | P1: OrderPlaced | Q1: OrderPipe1 | R1: OrderPipe2 | S1: ShipPipe1 | T1: ShipPipe2 | U1: InventoryPos | V1: TargetLevel | W1: SuggestedOrder
A2: 1 | B2: 0 | C2: 0 | D2: 50 | E2: 100 | F2: 0 | G2: 0 | H2: 0 | I2: 150 | J2: 0 | K2: 37.5 | L2: 0 | M2: 37.5 | N2: 37.5 | P2: 400 | Q2: 0 | R2: 0 | S2: 0 | T2: 0 | U2: 0 | V2: 0 | W2: 0
A3: 2 | B3: 0 | C3: 0 | D3: 50 | E3: 150 | F3: 0 | G3: 0 | H3: 0 | I3: 200 | J3: 0 | K3: 50 | L3: 0 | M3: 50 | N3: 87.5 | P3: 300 | Q3: 0 | R3: 0 | S3: 0 | T3: 0 | U3: 0 | V3: 0 | W3: 0
A4: 3 | B4: 200 | C4: 200 | D4: 0 | E4: 200 | F4: 0 | G4: 200 | H4: 200 | I4: 0 | J4: 0 | K4: 0 | L4: 0 | M4: 0 | N4: 87.5 | P4: 500 | Q4: 0 | R4: 0 | S4: 0 | T4: 0 | U4: 0 | V4: 0 | W4: 0
A5: 4 | B5: 200 | C5: 200 | D5: 0 | E5: 0 | F5: 0 | G5: 200 | H5: 0 | I5: 0 | J5: 200 | K5: 0 | L5: 200 | M5: 200 | N5: 287.5 | P5: 300 | Q5: 0 | R5: 0 | S5: 0 | T5: 0 | U5: 0 | V5: 0 | W5: 0
A6: 5 | B6: 491 | C6: 491 | D6: 400 | E6: 0 | F6: 200 | G6: 691 | H6: 400 | I6: 0 | J6: 291 | K6: 0 | L6: 291 | M6: 291 | N6: 578.5 | P6: 391 | Q6: 0 | R6: 0 | S6: 0 | T6: 0 | U6: 0 | V6: 0 | W6: 0
A7: 6 | B7: 721 | C7: 721 | D7: 300 | E7: 0 | F7: 291 | G7: 1012 | H7: 300 | I7: 0 | J7: 712 | K7: 0 | L7: 712 | M7: 712 | N7: 1290.5 | P7: 612 | Q7: 0 | R7: 0 | S7: 0 | T7: 0 | U7: 0 | V7: 0 | W7: 0
A8: 7 | B8: 1260 | C8: 1260 | D8: 500 | E8: 0 | F8: 712 | G8: 1972 | H8: 500 | I8: 0 | J8: 1472 | K8: 0 | L8: 1472 | M8: 1472 | N8: 2762.5 | P8: 1572 | Q8: 0 | R8: 0 | S8: 0 | T8: 0 | U8: 0 | V8: 0 | W8: 0
A9: 8 | B9: 1326 | C9: 1326 | D9: 300 | E9: 0 | F9: 1472 | G9: 2798 | H9: 300 | I9: 0 | J9: 2498 | K9: 0 | L9: 2498 | M9: 2498 | N9: 5260.5 | P9: 2507 | Q9: 0 | R9: 0 | S9: 0 | T9: 0 | U9: 0 | V9: 0 | W9: 0
A10: 9 | B10: 1595 | C10: 1595 | D10: 391 | E10: 0 | F10: 2498 | G10: 4093 | H10: 391 | I10: 0 | J10: 3702 | K10: 0 | L10: 3702 | M10: 3702 | N10: 8962.5 | P10: 3693 | Q10: 0 | R10: 0 | S10: 0 | T10: 0 | U10: 0 | V10: 0 | W10: 0
A11: 10 | B11: 1615 | C11: 1615 | D11: 409 | E11: 0 | F11: 3702 | G11: 5317 | H11: 409 | I11: 0 | J11: 4908 | K11: 0 | L11: 4908 | M11: 4908 | N11: 13870.5 | P11: 4917 | Q11: 0 | R11: 0 | S11: 0 | T11: 0 | U11: 0 | V11: 0 | W11: 0
A12: 11 | B12: 1932 | C12: 1932 | D12: 391 | E12: 0 | F12: 4908 | G12: 6840 | H12: 391 | I12: 0 | J12: 6449 | K12: 0 | L12: 6449 | M12: 6449 | N12: 20319.5 | P12: 6237 | Q12: 0 | R12: 0 | S12: 0 | T12: 0 | U12: 0 | V12: 0 | W12: 0
A13: 12 | B13: 1891 | C13: 1891 | D13: 612 | E13: 0 | F13: 6449 | G13: 8340 | H13: 612 | I13: 0 | J13: 7728 | K13: 0 | L13: 7728 | M13: 7728 | N13: 28047.5 | P13: 6556 | Q13: 0 | R13: 0 | S13: 0 | T13: 0 | U13: 0 | V13: 0 | W13: 0
... A36: 35 | B36: 0 | C36: 0 | D36: 0 | E36: 22362 | F36: 0 | G36: 0 | H36: 0 | I36: 22362 | J36: 0 | K36: 5590.5 | L36: 0 | M36: 5590.5 | N36: 146147.25 | P36: 0 | Q36: 0 | R36: 0 | S36: 0 | T36: 0 | U36: 0 | V36: 0 | W36: 0

Sheet S1_D3_Factory
A1: Week | B1: CustomerDemand | C1: In | D1: Recv | E1: BegInv | F1: BegBacklog | G1: TotalReq | H1: Ship | I1: EndInv | J1: EndBacklog | K1: InvCost | L1: BackCost | M1: WeekCost | N1: CumulativeCost | O1: OrderManual | P1: OrderPlaced | Q1: OrderPipe1 | R1: OrderPipe2 | S1: ShipPipe1 | T1: ShipPipe2 | U1: InventoryPos | V1: TargetLevel | W1: SuggestedOrder
A2: 1 | B2: 0 | C2: 0 | D2: 50 | E2: 100 | F2: 0 | G2: 0 | H2: 0 | I2: 150 | J2: 0 | K2: 37.5 | L2: 0 | M2: 37.5 | N2: 37.5 | P2: 600 | Q2: 0 | R2: 0 | S2: 0 | T2: 0 | U2: 0 | V2: 0 | W2: 0
A3: 2 | B3: 0 | C3: 0 | D3: 50 | E3: 150 | F3: 0 | G3: 0 | H3: 0 | I3: 200 | J3: 0 | K3: 50 | L3: 0 | M3: 50 | N3: 87.5 | P3: 0 | Q3: 0 | R3: 0 | S3: 0 | T3: 0 | U3: 0 | V3: 0 | W3: 0
A4: 3 | B4: 400 | C4: 400 | D4: 600 | E4: 200 | F4: 0 | G4: 400 | H4: 400 | I4: 400 | J4: 0 | K4: 100 | L4: 0 | M4: 100 | N4: 187.5 | P4: 400 | Q4: 0 | R4: 0 | S4: 0 | T4: 0 | U4: 0 | V4: 0 | W4: 0
A5: 4 | B5: 300 | C5: 300 | D5: 0 | E5: 400 | F5: 0 | G5: 300 | H5: 300 | I5: 100 | J5: 0 | K5: 25 | L5: 0 | M5: 25 | N5: 212.5 | P5: 300 | Q5: 0 | R5: 0 | S5: 0 | T5: 0 | U5: 0 | V5: 0 | W5: 0
A6: 5 | B6: 500 | C6: 500 | D6: 400 | E6: 100 | F6: 0 | G6: 500 | H6: 500 | I6: 0 | J6: 0 | K6: 0 | L6: 0 | M6: 0 | N6: 212.5 | P6: 500 | Q6: 0 | R6: 0 | S6: 0 | T6: 0 | U6: 0 | V6: 0 | W6: 0
A7: 6 | B7: 300 | C7: 300 | D7: 300 | E7: 0 | F7: 0 | G7: 300 | H7: 300 | I7: 0 | J7: 0 | K7: 0 | L7: 0 | M7: 0 | N7: 212.5 | P7: 300 | Q7: 0 | R7: 0 | S7: 0 | T7: 0 | U7: 0 | V7: 0 | W7: 0
A8: 7 | B8: 391 | C8: 391 | D8: 500 | E8: 0 | F8: 0 | G8: 391 | H8: 391 | I8: 109 | J8: 0 | K8: 27.25 | L8: 0 | M8: 27.25 | N8: 239.75 | P8: 391 | Q8: 0 | R8: 0 | S8: 0 | T8: 0 | U8: 0 | V8: 0 | W8: 0
A9: 8 | B9: 612 | C9: 612 | D9: 300 | E9: 109 | F9: 0 | G9: 612 | H9: 409 | I9: 0 | J9: 203 | K9: 0 | L9: 203 | M9: 203 | N9: 442.75 | P9: 612 | Q9: 0 | R9: 0 | S9: 0 | T9: 0 | U9: 0 | V9: 0 | W9: 0
A10: 9 | B10: 1572 | C10: 1572 | D10: 391 | E10: 0 | F10: 203 | G10: 1775 | H10: 391 | I10: 0 | J10: 1384 | K10: 0 | L10: 1384 | M10: 1384 | N10: 1826.75 | P10: 1572 | Q10: 0 | R10: 0 | S10: 0 | T10: 0 | U10: 0 | V10: 0 | W10: 0
A11: 10 | B11: 2507 | C11: 2507 | D11: 612 | E11: 0 | F11: 1384 | G11: 3891 | H11: 612 | I11: 0 | J11: 3279 | K11: 0 | L11: 3279 | M11: 3279 | N11: 5105.75 | P11: 2507 | Q11: 0 | R11: 0 | S11: 0 | T11: 0 | U11: 0 | V11: 0 | W11: 0
A12: 11 | B12: 3693 | C12: 3693 | D12: 1572 | E12: 0 | F12: 3279 | G12: 6972 | H12: 1572 | I12: 0 | J12: 5400 | K12: 0 | L12: 5400 | M12: 5400 | N12: 10505.75 | P12: 3693 | Q12: 0 | R12: 0 | S12: 0 | T12: 0 | U12: 0 | V12: 0 | W12: 0
A13: 12 | B13: 4917 | C13: 4917 | D13: 2507 | E13: 0 | F13: 5400 | G13: 10317 | H13: 2507 | I13: 0 | J13: 7810 | K13: 0 | L13: 7810 | M13: 7810 | N13: 18315.75 | P13: 4917 | Q13: 0 | R13: 0 | S13: 0 | T13: 0 | U13: 0 | V13: 0 | W13: 0
... A36: 35 | B36: 0 | C36: 0 | D36: 0 | E36: 400 | F36: 0 | G36: 0 | H36: 0 | I36: 400 | J36: 0 | K36: 100 | L36: 0 | M36: 100 | N36: 64528.75 | P36: 0 | Q36: 0 | R36: 0 | S36: 0 | T36: 0 | U36: 0 | V36: 0 | W36: 0

Sheet Scn1_View
A1: Simulation - Scenario 1 - HighInv
A2: Edit Inputs to change demand, costs, and policy parameters.
B3: Retailer | L3: Wholesaler | V3: Distributor | AF3: Factory | AP3: Total
B4: Incoming order | C4: Incoming shipment | D4: Outgoing shipment | E4: Inventory | F4: Backlog | G4: Order placed | H4: InvCost | I4: BackCost | J4: WeekCost | K4: Cumulative | L4: Incoming order | M4: Incoming shipment | N4: Outgoing shipment | O4: Inventory | P4: Backlog | Q4: Order placed | R4: InvCost | S4: BackCost | T4: WeekCost | U4: Cumulative | V4: Incoming order | W4: Incoming shipment | X4: Outgoing shipment | Y4: Inventory | Z4: Backlog | AA4: Order placed | AB4: InvCost | AC4: BackCost | AD4: WeekCost | AE4: Cumulative | AF4: Incoming order | AG4: Incoming shipment | AH4: Outgoing shipment | AI4: Inventory | AJ4: Backlog | AK4: Order placed | AL4: InvCost | AM4: BackCost | AN4: WeekCost | AO4: Cumulative | AP4: TotInvCost | AQ4: TotBackCost | AR4: TotWeekCost | AS4: CumCost
A5: 1 | B5: =CHOOSE(Inputs!$B$12,'S1_D1_Retailer'!C2,'S1_D2_Retailer'!C2,'S1_D3_Retailer'!C2) | C5: =CHOOSE(Inputs!$B$12,'S1_D1_Retailer'!D2,'S1_D2_Retailer'!D2,'S1_D3_Retailer'!D2) | D5: =CHOOSE(Inputs!$B$12,'S1_D1_Retailer'!H2,'S1_D2_Retailer'!H2,'S1_D3_Retailer'!H2) | E5: =CHOOSE(Inputs!$B$12,'S1_D1_Retailer'!I2,'S1_D2_Retailer'!I2,'S1_D3_Retailer'!I2) | F5: =CHOOSE(Inputs!$B$12,'S1_D1_Retailer'!J2,'S1_D2_Retailer'!J2,'S1_D3_Retailer'!J2) | G5: =CHOOSE(Inputs!$B$12,'S1_D1_Retailer'!P2,'S1_D2_Retailer'!P2,'S1_D3_Retailer'!P2) | H5: =CHOOSE(Inputs!$B$12,'S1_D1_Retailer'!K2,'S1_D2_Retailer'!K2,'S1_D3_Retailer'!K2) | I5: =CHOOSE(Inputs!$B$12,'S1_D1_Retailer'!L2,'S1_D2_Retailer'!L2,'S1_D3_Retailer'!L2) | J5: =CHOOSE(Inputs!$B$12,'S1_D1_Retailer'!M2,'S1_D2_Retailer'!M2,'S1_D3_Retailer'!M2) | K5: =CHOOSE(Inputs!$B$12,'S1_D1_Retailer'!N2,'S1_D2_Retailer'!N2,'S1_D3_Retailer'!N2) | L5: =CHOOSE(Inputs!$B$12,'S1_D1_Wholesaler'!C2,'S1_D2_Wholesaler'!C2,'S1_D3_Wholesaler'!C2) | M5: =CHOOSE(Inputs!$B$12,'S1_D1_Wholesaler'!D2,'S1_D2_Wholesaler'!D2,'S1_D3_Wholesaler'!D2) | N5: =CHOOSE(Inputs!$B$12,'S1_D1_Wholesaler'!H2,'S1_D2_Wholesaler'!H2,'S1_D3_Wholesaler'!H2) | O5: =CHOOSE(Inputs!$B$12,'S1_D1_Wholesaler'!I2,'S1_D2_Wholesaler'!I2,'S1_D3_Wholesaler'!I2) | P5: =CHOOSE(Inputs!$B$12,'S1_D1_Wholesaler'!J2,'S1_D2_Wholesaler'!J2,'S1_D3_Wholesaler'!J2) | Q5: =CHOOSE(Inputs!$B$12,'S1_D1_Wholesaler'!P2,'S1_D2_Wholesaler'!P2,'S1_D3_Wholesaler'!P2) | R5: =CHOOSE(Inputs!$B$12,'S1_D1_Wholesaler'!K2,'S1_D2_Wholesaler'!K2,'S1_D3_Wholesaler'!K2) | S5: =CHOOSE(Inputs!$B$12,'S1_D1_Wholesaler'!L2,'S1_D2_Wholesaler'!L2,'S1_D3_Wholesaler'!L2) | T5: =CHOOSE(Inputs!$B$12,'S1_D1_Wholesaler'!M2,'S1_D2_Wholesaler'!M2,'S1_D3_Wholesaler'!M2) | U5: =CHOOSE(Inputs!$B$12,'S1_D1_Wholesaler'!N2,'S1_D2_Wholesaler'!N2,'S1_D3_Wholesaler'!N2) | V5: =CHOOSE(Inputs!$B$12,'S1_D1_Distributor'!C2,'S1_D2_Distributor'!C2,'S1_D3_Distributor'!C2) | W5: =CHOOSE(Inputs!$B$12,'S1_D1_Distributor'!D2,'S1_D2_Distributor'!D2,'S1_D3_Distributor'!D2) | X5: =CHOOSE(Inputs!$B$12,'S1_D1_Distributor'!H2,'S1_D2_Distributor'!H2,'S1_D3_Distributor'!H2) | Y5: =CHOOSE(Inputs!$B$12,'S1_D1_Distributor'!I2,'S1_D2_Distributor'!I2,'S1_D3_Distributor'!I2) | Z5: =CHOOSE(Inputs!$B$12,'S1_D1_Distributor'!J2,'S1_D2_Distributor'!J2,'S1_D3_Distributor'!J2) | AA5: =CHOOSE(Inputs!$B$12,'S1_D1_Distributor'!P2,'S1_D2_Distributor'!P2,'S1_D3_Distributor'!P2) | AB5: =CHOOSE(Inputs!$B$12,'S1_D1_Distributor'!K2,'S1_D2_Distributor'!K2,'S1_D3_Distributor'!K2) | AC5: =CHOOSE(Inputs!$B$12,'S1_D1_Distributor'!L2,'S1_D2_Distributor'!L2,'S1_D3_Distributor'!L2) | AD5: =CHOOSE(Inputs!$B$12,'S1_D1_Distributor'!M2,'S1_D2_Distributor'!M2,'S1_D3_Distributor'!M2) | AE5: =CHOOSE(Inputs!$B$12,'S1_D1_Distributor'!N2,'S1_D2_Distributor'!N2,'S1_D3_Distributor'!N2) | AF5: =CHOOSE(Inputs!$B$12,'S1_D1_Factory'!C2,'S1_D2_Factory'!C2,'S1_D3_Factory'!C2) | AG5: =CHOOSE(Inputs!$B$12,'S1_D1_Factory'!D2,'S1_D2_Factory'!D2,'S1_D3_Factory'!D2) | AH5: =CHOOSE(Inputs!$B$12,'S1_D1_Factory'!H2,'S1_D2_Factory'!H2,'S1_D3_Factory'!H2) | AI5: =CHOOSE(Inputs!$B$12,'S1_D1_Factory'!I2,'S1_D2_Factory'!I2,'S1_D3_Factory'!I2) | AJ5: =CHOOSE(Inputs!$B$12,'S1_D1_Factory'!J2,'S1_D2_Factory'!J2,'S1_D3_Factory'!J2) | AK5: =CHOOSE(Inputs!$B$12,'S1_D1_Factory'!P2,'S1_D2_Factory'!P2,'S1_D3_Factory'!P2) | AL5: =CHOOSE(Inputs!$B$12,'S1_D1_Factory'!K2,'S1_D2_Factory'!K2,'S1_D3_Factory'!K2) | AM5: =CHOOSE(Inputs!$B$12,'S1_D1_Factory'!L2,'S1_D2_Factory'!L2,'S1_D3_Factory'!L2) | AN5: =CHOOSE(Inputs!$B$12,'S1_D1_Factory'!M2,'S1_D2_Factory'!M2,'S1_D3_Factory'!M2) | AO5: =CHOOSE(Inputs!$B$12,'S1_D1_Factory'!N2,'S1_D2_Factory'!N2,'S1_D3_Factory'!N2) | AP5: =SUM(H5,R5,AB5,AL5) | AQ5: =SUM(I5,S5,AC5,AM5) | AR5: =SUM(J5,T5,AD5,AN5) | AS5: =AR5
A6: 2 | B6: =CHOOSE(Inputs!$B$12,'S1_D1_Retailer'!C3,'S1_D2_Retailer'!C3,'S1_D3_Retailer'!C3) | C6: =CHOOSE(Inputs!$B$12,'S1_D1_Retailer'!D3,'S1_D2_Retailer'!D3,'S1_D3_Retailer'!D3) | D6: =CHOOSE(Inputs!$B$12,'S1_D1_Retailer'!H3,'S1_D2_Retailer'!H3,'S1_D3_Retailer'!H3) | E6: =CHOOSE(Inputs!$B$12,'S1_D1_Retailer'!I3,'S1_D2_Retailer'!I3,'S1_D3_Retailer'!I3) | F6: =CHOOSE(Inputs!$B$12,'S1_D1_Retailer'!J3,'S1_D2_Retailer'!J3,'S1_D3_Retailer'!J3) | G6: =CHOOSE(Inputs!$B$12,'S1_D1_Retailer'!P3,'S1_D2_Retailer'!P3,'S1_D3_Retailer'!P3) | H6: =CHOOSE(Inputs!$B$12,'S1_D1_Retailer'!K3,'S1_D2_Retailer'!K3,'S1_D3_Retailer'!K3) | I6: =CHOOSE(Inputs!$B$12,'S1_D1_Retailer'!L3,'S1_D2_Retailer'!L3,'S1_D3_Retailer'!L3) | J6: =CHOOSE(Inputs!$B$12,'S1_D1_Retailer'!M3,'S1_D2_Retailer'!M3,'S1_D3_Retailer'!M3) | K6: =CHOOSE(Inputs!$B$12,'S1_D1_Retailer'!N3,'S1_D2_Retailer'!N3,'S1_D3_Retailer'!N3) | L6: =CHOOSE(Inputs!$B$12,'S1_D1_Wholesaler'!C3,'S1_D2_Wholesaler'!C3,'S1_D3_Wholesaler'!C3) | M6: =CHOOSE(Inputs!$B$12,'S1_D1_Wholesaler'!D3,'S1_D2_Wholesaler'!D3,'S1_D3_Wholesaler'!D3) | N6: =CHOOSE(Inputs!$B$12,'S1_D1_Wholesaler'!H3,'S1_D2_Wholesaler'!H3,'S1_D3_Wholesaler'!H3) | O6: =CHOOSE(Inputs!$B$12,'S1_D1_Wholesaler'!I3,'S1_D2_Wholesaler'!I3,'S1_D3_Wholesaler'!I3) | P6: =CHOOSE(Inputs!$B$12,'S1_D1_Wholesaler'!J3,'S1_D2_Wholesaler'!J3,'S1_D3_Wholesaler'!J3) | Q6: =CHOOSE(Inputs!$B$12,'S1_D1_Wholesaler'!P3,'S1_D2_Wholesaler'!P3,'S1_D3_Wholesaler'!P3) | R6: =CHOOSE(Inputs!$B$12,'S1_D1_Wholesaler'!K3,'S1_D2_Wholesaler'!K3,'S1_D3_Wholesaler'!K3) | S6: =CHOOSE(Inputs!$B$12,'S1_D1_Wholesaler'!L3,'S1_D2_Wholesaler'!L3,'S1_D3_Wholesaler'!L3) | T6: =CHOOSE(Inputs!$B$12,'S1_D1_Wholesaler'!M3,'S1_D2_Wholesaler'!M3,'S1_D3_Wholesaler'!M3) | U6: =CHOOSE(Inputs!$B$12,'S1_D1_Wholesaler'!N3,'S1_D2_Wholesaler'!N3,'S1_D3_Wholesaler'!N3) | V6: =CHOOSE(Inputs!$B$12,'S1_D1_Distributor'!C3,'S1_D2_Distributor'!C3,'S1_D3_Distributor'!C3) | W6: =CHOOSE(Inputs!$B$12,'S1_D1_Distributor'!D3,'S1_D2_Distributor'!D3,'S1_D3_Distributor'!D3) | X6: =CHOOSE(Inputs!$B$12,'S1_D1_Distributor'!H3,'S1_D2_Distributor'!H3,'S1_D3_Distributor'!H3) | Y6: =CHOOSE(Inputs!$B$12,'S1_D1_Distributor'!I3,'S1_D2_Distributor'!I3,'S1_D3_Distributor'!I3) | Z6: =CHOOSE(Inputs!$B$12,'S1_D1_Distributor'!J3,'S1_D2_Distributor'!J3,'S1_D3_Distributor'!J3) | AA6: =CHOOSE(Inputs!$B$12,'S1_D1_Distributor'!P3,'S1_D2_Distributor'!P3,'S1_D3_Distributor'!P3) | AB6: =CHOOSE(Inputs!$B$12,'S1_D1_Distributor'!K3,'S1_D2_Distributor'!K3,'S1_D3_Distributor'!K3) | AC6: =CHOOSE(Inputs!$B$12,'S1_D1_Distributor'!L3,'S1_D2_Distributor'!L3,'S1_D3_Distributor'!L3) | AD6: =CHOOSE(Inputs!$B$12,'S1_D1_Distributor'!M3,'S1_D2_Distributor'!M3,'S1_D3_Distributor'!M3) | AE6: =CHOOSE(Inputs!$B$12,'S1_D1_Distributor'!N3,'S1_D2_Distributor'!N3,'S1_D3_Distributor'!N3) | AF6: =CHOOSE(Inputs!$B$12,'S1_D1_Factory'!C3,'S1_D2_Factory'!C3,'S1_D3_Factory'!C3) | AG6: =CHOOSE(Inputs!$B$12,'S1_D1_Factory'!D3,'S1_D2_Factory'!D3,'S1_D3_Factory'!D3) | AH6: =CHOOSE(Inputs!$B$12,'S1_D1_Factory'!H3,'S1_D2_Factory'!H3,'S1_D3_Factory'!H3) | AI6: =CHOOSE(Inputs!$B$12,'S1_D1_Factory'!I3,'S1_D2_Factory'!I3,'S1_D3_Factory'!I3) | AJ6: =CHOOSE(Inputs!$B$12,'S1_D1_Factory'!J3,'S1_D2_Factory'!J3,'S1_D3_Factory'!J3) | AK6: =CHOOSE(Inputs!$B$12,'S1_D1_Factory'!P3,'S1_D2_Factory'!P3,'S1_D3_Factory'!P3) | AL6: =CHOOSE(Inputs!$B$12,'S1_D1_Factory'!K3,'S1_D2_Factory'!K3,'S1_D3_Factory'!K3) | AM6: =CHOOSE(Inputs!$B$12,'S1_D1_Factory'!L3,'S1_D2_Factory'!L3,'S1_D3_Factory'!L3) | AN6: =CHOOSE(Inputs!$B$12,'S1_D1_Factory'!M3,'S1_D2_Factory'!M3,'S1_D3_Factory'!M3) | AO6: =CHOOSE(Inputs!$B$12,'S1_D1_Factory'!N3,'S1_D2_Factory'!N3,'S1_D3_Factory'!N3) | AP6: =SUM(H6,R6,AB6,AL6) | AQ6: =SUM(I6,S6,AC6,AM6) | AR6: =SUM(J6,T6,AD6,AN6) | AS6: =AS5+AR6
A7: 3 | B7: =CHOOSE(Inputs!$B$12,'S1_D1_Retailer'!C4,'S1_D2_Retailer'!C4,'S1_D3_Retailer'!C4) | C7: =CHOOSE(Inputs!$B$12,'S1_D1_Retailer'!D4,'S1_D2_Retailer'!D4,'S1_D3_Retailer'!D4) | D7: =CHOOSE(Inputs!$B$12,'S1_D1_Retailer'!H4,'S1_D2_Retailer'!H4,'S1_D3_Retailer'!H4) | E7: =CHOOSE(Inputs!$B$12,'S1_D1_Retailer'!I4,'S1_D2_Retailer'!I4,'S1_D3_Retailer'!I4) | F7: =CHOOSE(Inputs!$B$12,'S1_D1_Retailer'!J4,'S1_D2_Retailer'!J4,'S1_D3_Retailer'!J4) | G7: =CHOOSE(Inputs!$B$12,'S1_D1_Retailer'!P4,'S1_D2_Retailer'!P4,'S1_D3_Retailer'!P4) | H7: =CHOOSE(Inputs!$B$12,'S1_D1_Retailer'!K4,'S1_D2_Retailer'!K4,'S1_D3_Retailer'!K4) | I7: =CHOOSE(Inputs!$B$12,'S1_D1_Retailer'!L4,'S1_D2_Retailer'!L4,'S1_D3_Retailer'!L4) | J7: =CHOOSE(Inputs!$B$12,'S1_D1_Retailer'!M4,'S1_D2_Retailer'!M4,'S1_D3_Retailer'!M4) | K7: =CHOOSE(Inputs!$B$12,'S1_D1_Retailer'!N4,'S1_D2_Retailer'!N4,'S1_D3_Retailer'!N4) | L7: =CHOOSE(Inputs!$B$12,'S1_D1_Wholesaler'!C4,'S1_D2_Wholesaler'!C4,'S1_D3_Wholesaler'!C4) | M7: =CHOOSE(Inputs!$B$12,'S1_D1_Wholesaler'!D4,'S1_D2_Wholesaler'!D4,'S1_D3_Wholesaler'!D4) | N7: =CHOOSE(Inputs!$B$12,'S1_D1_Wholesaler'!H4,'S1_D2_Wholesaler'!H4,'S1_D3_Wholesaler'!H4) | O7: =CHOOSE(Inputs!$B$12,'S1_D1_Wholesaler'!I4,'S1_D2_Wholesaler'!I4,'S1_D3_Wholesaler'!I4) | P7: =CHOOSE(Inputs!$B$12,'S1_D1_Wholesaler'!J4,'S1_D2_Wholesaler'!J4,'S1_D3_Wholesaler'!J4) | Q7: =CHOOSE(Inputs!$B$12,'S1_D1_Wholesaler'!P4,'S1_D2_Wholesaler'!P4,'S1_D3_Wholesaler'!P4) | R7: =CHOOSE(Inputs!$B$12,'S1_D1_Wholesaler'!K4,'S1_D2_Wholesaler'!K4,'S1_D3_Wholesaler'!K4) | S7: =CHOOSE(Inputs!$B$12,'S1_D1_Wholesaler'!L4,'S1_D2_Wholesaler'!L4,'S1_D3_Wholesaler'!L4) | T7: =CHOOSE(Inputs!$B$12,'S1_D1_Wholesaler'!M4,'S1_D2_Wholesaler'!M4,'S1_D3_Wholesaler'!M4) | U7: =CHOOSE(Inputs!$B$12,'S1_D1_Wholesaler'!N4,'S1_D2_Wholesaler'!N4,'S1_D3_Wholesaler'!N4) | V7: =CHOOSE(Inputs!$B$12,'S1_D1_Distributor'!C4,'S1_D2_Distributor'!C4,'S1_D3_Distributor'!C4) | W7: =CHOOSE(Inputs!$B$12,'S1_D1_Distributor'!D4,'S1_D2_Distributor'!D4,'S1_D3_Distributor'!D4) | X7: =CHOOSE(Inputs!$B$12,'S1_D1_Distributor'!H4,'S1_D2_Distributor'!H4,'S1_D3_Distributor'!H4) | Y7: =CHOOSE(Inputs!$B$12,'S1_D1_Distributor'!I4,'S1_D2_Distributor'!I4,'S1_D3_Distributor'!I4) | Z7: =CHOOSE(Inputs!$B$12,'S1_D1_Distributor'!J4,'S1_D2_Distributor'!J4,'S1_D3_Distributor'!J4) | AA7: =CHOOSE(Inputs!$B$12,'S1_D1_Distributor'!P4,'S1_D2_Distributor'!P4,'S1_D3_Distributor'!P4) | AB7: =CHOOSE(Inputs!$B$12,'S1_D1_Distributor'!K4,'S1_D2_Distributor'!K4,'S1_D3_Distributor'!K4) | AC7: =CHOOSE(Inputs!$B$12,'S1_D1_Distributor'!L4,'S1_D2_Distributor'!L4,'S1_D3_Distributor'!L4) | AD7: =CHOOSE(Inputs!$B$12,'S1_D1_Distributor'!M4,'S1_D2_Distributor'!M4,'S1_D3_Distributor'!M4) | AE7: =CHOOSE(Inputs!$B$12,'S1_D1_Distributor'!N4,'S1_D2_Distributor'!N4,'S1_D3_Distributor'!N4) | AF7: =CHOOSE(Inputs!$B$12,'S1_D1_Factory'!C4,'S1_D2_Factory'!C4,'S1_D3_Factory'!C4) | AG7: =CHOOSE(Inputs!$B$12,'S1_D1_Factory'!D4,'S1_D2_Factory'!D4,'S1_D3_Factory'!D4) | AH7: =CHOOSE(Inputs!$B$12,'S1_D1_Factory'!H4,'S1_D2_Factory'!H4,'S1_D3_Factory'!H4) | AI7: =CHOOSE(Inputs!$B$12,'S1_D1_Factory'!I4,'S1_D2_Factory'!I4,'S1_D3_Factory'!I4) | AJ7: =CHOOSE(Inputs!$B$12,'S1_D1_Factory'!J4,'S1_D2_Factory'!J4,'S1_D3_Factory'!J4) | AK7: =CHOOSE(Inputs!$B$12,'S1_D1_Factory'!P4,'S1_D2_Factory'!P4,'S1_D3_Factory'!P4) | AL7: =CHOOSE(Inputs!$B$12,'S1_D1_Factory'!K4,'S1_D2_Factory'!K4,'S1_D3_Factory'!K4) | AM7: =CHOOSE(Inputs!$B$12,'S1_D1_Factory'!L4,'S1_D2_Factory'!L4,'S1_D3_Factory'!L4) | AN7: =CHOOSE(Inputs!$B$12,'S1_D1_Factory'!M4,'S1_D2_Factory'!M4,'S1_D3_Factory'!M4) | AO7: =CHOOSE(Inputs!$B$12,'S1_D1_Factory'!N4,'S1_D2_Factory'!N4,'S1_D3_Factory'!N4) | AP7: =SUM(H7,R7,AB7,AL7) | AQ7: =SUM(I7,S7,AC7,AM7) | AR7: =SUM(J7,T7,AD7,AN7) | AS7: =AS6+AR7
A8: 4 | B8: =CHOOSE(Inputs!$B$12,'S1_D1_Retailer'!C5,'S1_D2_Retailer'!C5,'S1_D3_Retailer'!C5) | C8: =CHOOSE(Inputs!$B$12,'S1_D1_Retailer'!D5,'S1_D2_Retailer'!D5,'S1_D3_Retailer'!D5) | D8: =CHOOSE(Inputs!$B$12,'S1_D1_Retailer'!H5,'S1_D2_Retailer'!H5,'S1_D3_Retailer'!H5) | E8: =CHOOSE(Inputs!$B$12,'S1_D1_Retailer'!I5,'S1_D2_Retailer'!I5,'S1_D3_Retailer'!I5) | F8: =CHOOSE(Inputs!$B$12,'S1_D1_Retailer'!J5,'S1_D2_Retailer'!J5,'S1_D3_Retailer'!J5) | G8: =CHOOSE(Inputs!$B$12,'S1_D1_Retailer'!P5,'S1_D2_Retailer'!P5,'S1_D3_Retailer'!P5) | H8: =CHOOSE(Inputs!$B$12,'S1_D1_Retailer'!K5,'S1_D2_Retailer'!K5,'S1_D3_Retailer'!K5) | I8: =CHOOSE(Inputs!$B$12,'S1_D1_Retailer'!L5,'S1_D2_Retailer'!L5,'S1_D3_Retailer'!L5) | J8: =CHOOSE(Inputs!$B$12,'S1_D1_Retailer'!M5,'S1_D2_Retailer'!M5,'S1_D3_Retailer'!M5) | K8: =CHOOSE(Inputs!$B$12,'S1_D1_Retailer'!N5,'S1_D2_Retailer'!N5,'S1_D3_Retailer'!N5) | L8: =CHOOSE(Inputs!$B$12,'S1_D1_Wholesaler'!C5,'S1_D2_Wholesaler'!C5,'S1_D3_Wholesaler'!C5) | M8: =CHOOSE(Inputs!$B$12,'S1_D1_Wholesaler'!D5,'S1_D2_Wholesaler'!D5,'S1_D3_Wholesaler'!D5) | N8: =CHOOSE(Inputs!$B$12,'S1_D1_Wholesaler'!H5,'S1_D2_Wholesaler'!H5,'S1_D3_Wholesaler'!H5) | O8: =CHOOSE(Inputs!$B$12,'S1_D1_Wholesaler'!I5,'S1_D2_Wholesaler'!I5,'S1_D3_Wholesaler'!I5) | P8: =CHOOSE(Inputs!$B$12,'S1_D1_Wholesaler'!J5,'S1_D2_Wholesaler'!J5,'S1_D3_Wholesaler'!J5) | Q8: =CHOOSE(Inputs!$B$12,'S1_D1_Wholesaler'!P5,'S1_D2_Wholesaler'!P5,'S1_D3_Wholesaler'!P5) | R8: =CHOOSE(Inputs!$B$12,'S1_D1_Wholesaler'!K5,'S1_D2_Wholesaler'!K5,'S1_D3_Wholesaler'!K5) | S8: =CHOOSE(Inputs!$B$12,'S1_D1_Wholesaler'!L5,'S1_D2_Wholesaler'!L5,'S1_D3_Wholesaler'!L5) | T8: =CHOOSE(Inputs!$B$12,'S1_D1_Wholesaler'!M5,'S1_D2_Wholesaler'!M5,'S1_D3_Wholesaler'!M5) | U8: =CHOOSE(Inputs!$B$12,'S1_D1_Wholesaler'!N5,'S1_D2_Wholesaler'!N5,'S1_D3_Wholesaler'!N5) | V8: =CHOOSE(Inputs!$B$12,'S1_D1_Distributor'!C5,'S1_D2_Distributor'!C5,'S1_D3_Distributor'!C5) | W8: =CHOOSE(Inputs!$B$12,'S1_D1_Distributor'!D5,'S1_D2_Distributor'!D5,'S1_D3_Distributor'!D5) | X8: =CHOOSE(Inputs!$B$12,'S1_D1_Distributor'!H5,'S1_D2_Distributor'!H5,'S1_D3_Distributor'!H5) | Y8: =CHOOSE(Inputs!$B$12,'S1_D1_Distributor'!I5,'S1_D2_Distributor'!I5,'S1_D3_Distributor'!I5) | Z8: =CHOOSE(Inputs!$B$12,'S1_D1_Distributor'!J5,'S1_D2_Distributor'!J5,'S1_D3_Distributor'!J5) | AA8: =CHOOSE(Inputs!$B$12,'S1_D1_Distributor'!P5,'S1_D2_Distributor'!P5,'S1_D3_Distributor'!P5) | AB8: =CHOOSE(Inputs!$B$12,'S1_D1_Distributor'!K5,'S1_D2_Distributor'!K5,'S1_D3_Distributor'!K5) | AC8: =CHOOSE(Inputs!$B$12,'S1_D1_Distributor'!L5,'S1_D2_Distributor'!L5,'S1_D3_Distributor'!L5) | AD8: =CHOOSE(Inputs!$B$12,'S1_D1_Distributor'!M5,'S1_D2_Distributor'!M5,'S1_D3_Distributor'!M5) | AE8: =CHOOSE(Inputs!$B$12,'S1_D1_Distributor'!N5,'S1_D2_Distributor'!N5,'S1_D3_Distributor'!N5) | AF8: =CHOOSE(Inputs!$B$12,'S1_D1_Factory'!C5,'S1_D2_Factory'!C5,'S1_D3_Factory'!C5) | AG8: =CHOOSE(Inputs!$B$12,'S1_D1_Factory'!D5,'S1_D2_Factory'!D5,'S1_D3_Factory'!D5) | AH8: =CHOOSE(Inputs!$B$12,'S1_D1_Factory'!H5,'S1_D2_Factory'!H5,'S1_D3_Factory'!H5) | AI8: =CHOOSE(Inputs!$B$12,'S1_D1_Factory'!I5,'S1_D2_Factory'!I5,'S1_D3_Factory'!I5) | AJ8: =CHOOSE(Inputs!$B$12,'S1_D1_Factory'!J5,'S1_D2_Factory'!J5,'S1_D3_Factory'!J5) | AK8: =CHOOSE(Inputs!$B$12,'S1_D1_Factory'!P5,'S1_D2_Factory'!P5,'S1_D3_Factory'!P5) | AL8: =CHOOSE(Inputs!$B$12,'S1_D1_Factory'!K5,'S1_D2_Factory'!K5,'S1_D3_Factory'!K5) | AM8: =CHOOSE(Inputs!$B$12,'S1_D1_Factory'!L5,'S1_D2_Factory'!L5,'S1_D3_Factory'!L5) | AN8: =CHOOSE(Inputs!$B$12,'S1_D1_Factory'!M5,'S1_D2_Factory'!M5,'S1_D3_Factory'!M5) | AO8: =CHOOSE(Inputs!$B$12,'S1_D1_Factory'!N5,'S1_D2_Factory'!N5,'S1_D3_Factory'!N5) | AP8: =SUM(H8,R8,AB8,AL8) | AQ8: =SUM(I8,S8,AC8,AM8) | AR8: =SUM(J8,T8,AD8,AN8) | AS8: =AS7+AR8
